Issue
  { issueClosedAt = Just 2015 (-04) (-20) 23 : 51 : 03 UTC
  , issueUpdatedAt = 2015 (-04) (-20) 23 : 51 : 08 UTC
  , issueEventsUrl =
      "https://api.github.com/repos/rethinkdb/rethinkdb/issues/4082/events"
  , issueHtmlUrl =
      Just "https://github.com/rethinkdb/rethinkdb/issues/4082"
  , issueClosedBy = Nothing
  , issueLabels = []
  , issueNumber = 4082
  , issueAssignee = Nothing
  , issueUser =
      SimpleUser
        { simpleUserId = Id 605076
        , simpleUserLogin = N "freak4pc"
        , simpleUserAvatarUrl =
            "https://avatars.githubusercontent.com/u/605076?v=3"
        , simpleUserUrl = "https://api.github.com/users/freak4pc"
        , simpleUserType = OwnerUser
        }
  , issueTitle = "Can't connect locally when using --bind all"
  , issuePullRequest = Nothing
  , issueUrl =
      "https://api.github.com/repos/rethinkdb/rethinkdb/issues/4082"
  , issueCreatedAt = 2015 (-04) (-20) 13 : 01 : 30 UTC
  , issueBody =
      Just
        "Hey All,\r\nI'm using thinky on node.js , \r\nWhen trying to connect to 127.0.0.1 after running \"rethinkdb\" it works fine, but if i ran \"rethinkdb --bind all\" , it wouldnt let me connect with the following errors:\r\n\r\n```\r\nFailed to connect to fe80::4fb:81e2:d4f9:a4a1%10:28015\r\nFull error:\r\n{\r\n  \"code\": \"EHOSTUNREACH\",\r\n  \"errno\": \"EHOSTUNREACH\",\r\n  \"syscall\": \"connect\"\r\n}.\r\nReqlDriverError: Failed to connect to fe80::4fb:81e2:d4f9:a4a1%10:28015\r\nFull error:\r\n{\r\n  \"code\": \"EHOSTUNREACH\",\r\n  \"errno\": \"EHOSTUNREACH\",\r\n  \"syscall\": \"connect\"\r\n}.\r\n    at Socket.<anonymous> (/Users/freak4pc/Work/DreamDate/DreamDate-API/node_modules/thinky/node_modules/rethinkdbdash/lib/connection.js:83:16)\r\n    at Socket.g (events.js:180:16)\r\n    at Socket.emit (events.js:95:17)\r\n    at net.js:440:14\r\n    at process._tickCallback (node.js:419:13)\r\nFail to create a new connection for the connection pool The error returned was:\r\nFailed to connect to fe80::4fb:81e2:d4f9:a4a1%10:28015\r\nFull error:\r\n{\r\n  \"code\": \"EHOSTUNREACH\",\r\n  \"errno\": \"EHOSTUNREACH\",\r\n  \"syscall\": \"connect\"\r\n}.\r\nReqlDriverError: Failed to connect to fe80::4fb:81e2:d4f9:a4a1%10:28015\r\nFull error:\r\n{\r\n  \"code\": \"EHOSTUNREACH\",\r\n  \"errno\": \"EHOSTUNREACH\",\r\n  \"syscall\": \"connect\"\r\n}.\r\n    at Socket.<anonymous> (/Users/freak4pc/Work/DreamDate/DreamDate-API/node_modules/thinky/node_modules/rethinkdbdash/lib/connection.js:83:16)\r\n    at Socket.g (events.js:180:16)\r\n    at Socket.emit (events.js:95:17)\r\n    at net.js:440:14\r\n    at process._tickCallback (node.js:419:13)\r\n```\r\n\r\nAm I doing anything wrong? "
  , issueState = "closed"
  , issueId = Id 69581771
  , issueComments = 6
  , issueMilestone =
      Just
        Milestone
          { milestoneCreator =
              SimpleUser
                { simpleUserId = Id 706854
                , simpleUserLogin = N "AtnNn"
                , simpleUserAvatarUrl =
                    "https://avatars.githubusercontent.com/u/706854?v=3"
                , simpleUserUrl = "https://api.github.com/users/AtnNn"
                , simpleUserType = OwnerUser
                }
          , milestoneDueOn = Nothing
          , milestoneOpenIssues = 0
          , milestoneNumber = 26
          , milestoneClosedIssues = 316
          , milestoneDescription =
              Just
                "These issues are neither bugs nor feature requests. Spam, user questions and accidentally created issues end up here."
          , milestoneTitle = "invalid"
          , milestoneUrl =
              "https://api.github.com/repos/rethinkdb/rethinkdb/milestones/26"
          , milestoneCreatedAt = 2013 (-04) (-05) 01 : 37 : 20 UTC
          , milestoneState = "closed"
          }
  }